Workbook

Sheet Inicio_Guía
B2: Plantilla de Análisis de Otorgamiento de Crédito Empresarial
B3: Caso ilustrativo: Industrias de Higiene Popular, C.A. (IHP) — cifras en USD miles, años 2023-2025
C5: Propósito de esta plantilla
C6: Esta plantilla apoya el análisis de otorgamiento de crédito a empresas productivas. Utiliza como ejemplo precargado el caso ficticio de Industrias de Higiene Popular, C.A. (IHP), una empresa de higiene y limpieza que solicita financiamiento para el proyecto Beauty Cream. Todas las cifras están en USD miles, salvo que se indique lo contrario. El caso es ficticio y de uso académico; sustituya los valores de entrada (celdas en azul) por los de la empresa real que esté evaluando.
C10: Flujo de uso recomendado
C11: 1. Cargar estados financieros
C12: Ingrese en 'ER_3Años', 'BG_3Años' y 'Flujo_3Años' los valores históricos de la empresa (celdas azules) para tres años consecutivos.
C15: 2. Revisar indicadores y gráficos
C16: La pestaña 'Indicadores' calcula automáticamente liquidez, endeudamiento, rentabilidad y ciclo de efectivo, con semáforo y gráficos de evolución.
C19: 3. Definir estructura de crédito y DSCR
C20: En 'Crédito_DSCR' ingrese monto, tasa, plazo, gracia y flujo disponible proyectado; la hoja calcula el servicio de deuda y el DSCR anual con semáforo.
C23: 4. Calcular Altman Z-Score
C24: En 'Altman_Z' se calcula el modelo de Altman original para cada año, con clasificación de zona segura, gris o de angustia.
C27: 5. Evaluar la decisión de crédito
... C35: Leyenda de colores (semáforo de indicadores)
C36: Verde — Aceptable | E36: El indicador se ubica dentro del rango deseable según la guía de referencia.
C37: Amarillo — Alerta | E37: El indicador se aproxima al límite aceptable; requiere seguimiento cercano.
C38: Rojo — Revisión | E38: El indicador está fuera del rango aceptable; requiere revisión y mitigantes antes de aprobar.
C40: Convención de colores del modelo
C41: Azul — Entradas editables | E41: Celdas que el analista debe sustituir por los datos de la empresa evaluada.
C42: Negro — Fórmulas | E42: Cálculos dentro de la misma hoja; no editar.
C43: Verde (texto) — Vínculos entre hojas | E43: Fórmulas que traen valores desde otra pestaña del libro; no editar.
C45: Nota importante sobre los rangos
C46: Los rangos de aceptación, alerta y revisión utilizados en esta plantilla son orientativos, basados en prácticas generales para empresas manufactureras. Deben ajustarse al sector, tamaño, moneda, estacionalidad y naturaleza del proyecto financiado. En el caso IHP, los insumos importados pagados de contado y la venta a crédito hacen que el DSO, el ciclo de conversión de efectivo y el DSCR sean particularmente relevantes para la decisión de crédito.
C50: Mapa de pestañas
C51: Inicio_Guía | E51: Esta hoja: flujo de uso y leyenda.
C52: ER_3Años | E52: Estado de resultados 2023-2025 (inputs azules).
C53: BG_3Años | E53: Balance general 2023-2025 (inputs azules) con chequeo de cuadre.
C54: Flujo_3Años | E54: Flujo de efectivo simplificado 2023-2025.
C55: Crédito_DSCR | E55: Términos del crédito propuesto y cálculo de DSCR 2026-2031.
C56: Indicadores | E56: Indicadores financieros automáticos con semáforo y gráficos.
C57: Altman_Z | E57: Modelo Altman Z-Score 2023-2025 y clasificación de zona.
C58: Matriz_Decisión | E58: Rúbrica de evaluación ponderada y decisión crediticia.
C59: Guía_Rangos | E59: Definiciones y umbrales de referencia de cada indicador.

Sheet ER_3Años
B2: Estado de Resultados — IHP
B3: Cifras en USD miles. Celdas azules = inputs editables. Sustituya por los datos de la empresa evaluada.
B5: Concepto (USD miles) | C5: 2023 | D5: 2024 | E5: 2025
B6: Ingresos por ventas | C6: 13200 | D6: 12600 | E6: 12000
B7: Costo de bienes vendidos (COGS) | C7: -8976 | D7: -8694 | E7: -8460
B8: Utilidad bruta | C8: =C6+C7 -> 4224 | D8: =D6+D7 -> 3906 | E8: =E6+E7 -> 3540
B9: Gastos administrativos, comerciales y operativos | C9: -1774 | D9: -1680 | E9: -1487
B10: Provisión para pérdidas crediticias | C10: -280 | D10: -350 | E10: -450
B11: Costos de contingencias laborales y paralizaciones | C11: -90 | D11: -110 | E11: -120
B12: Depreciación y amortización | C12: -60 | D12: -55 | E12: -50
B13: Resultado operativo (EBIT) | C13: =C8+C9+C10+C11+C12 -> 2020 | D13: =D8+D9+D10+D11+D12 -> 1711 | E13: =E8+E9+E10+E11+E12 -> 1433
B14: Gastos financieros, cambiarios y otros | C14: -180 | D14: -150 | E14: -130
B15: Resultado antes de impuesto | C15: =C13+C14 -> 1840 | D15: =D13+D14 -> 1561 | E15: =E13+E14 -> 1303
B16: Impuesto estimado | C16: -515 | D16: -437 | E16: -365
B17: Utilidad neta | C17: =C15+C16 -> 1325 | D17: =D15+D16 -> 1124 | E17: =E15+E16 -> 938
B19: EBITDA (EBIT + Depreciación y amortización) | C19: =C13-C12 -> 2080 | D19: =D13-D12 -> 1766 | E19: =E13-E12 -> 1483
B21: Nota: la depreciación se ingresa como valor negativo (gasto). EBITDA = EBIT - Depreciación y amortización (dado que la depreciación se resta con signo negativo, restarla nuevamente la revierte). Datos históricos de IHP tomados del caso de estudio 2023-2025; sustituya por los valores de la empresa real.

Sheet BG_3Años
B2: Balance General — IHP
B3: Cifras en USD miles. Celdas azules = inputs editables. Incluye chequeo automático de cuadre contable.
B5: Concepto (USD miles) | C5: 2023 | D5: 2024 | E5: 2025
B6: ACTIVOS
B7: Caja y equivalentes | C7: 1110 | D7: 1160 | E7: 1000
B8: Cuentas por cobrar comerciales, netas | C8: 3840 | D8: 3750 | E8: 3600
B9: Inventarios | C9: 1500 | D9: 1600 | E9: 1650
B10: Otros activos corrientes | C10: 260 | D10: 250 | E10: 250
B11: Total activos corrientes | C11: =SUM(C7:C10) -> 6710 | D11: =SUM(D7:D10) -> 6760 | E11: =SUM(E7:E10) -> 6500
B12: PP&E neto (propiedad, planta y equipo) | C12: 460 | D12: 440 | E12: 430
B13: Otros activos no corrientes | C13: 0 | D13: 0 | E13: 0
B14: Total activos | C14: =C11+C12+C13 -> 7170 | D14: =D11+D12+D13 -> 7200 | E14: =E11+E12+E13 -> 6930
B16: PASIVOS
B17: Cuentas por pagar a proveedores | C17: 500 | D17: 500 | E17: 480
B18: Deuda financiera de corto plazo | C18: 0 | D18: 0 | E18: 0
B19: Otros pasivos corrientes (nómina, tributos, contingencias) | C19: 480 | D19: 560 | E19: 950
B20: Total pasivos corrientes | C20: =SUM(C17:C19) -> 980 | D20: =SUM(D17:D19) -> 1060 | E20: =SUM(E17:E19) -> 1430
B21: Deuda financiera de largo plazo | C21: 0 | D21: 0 | E21: 0
B22: Otros pasivos no corrientes | C22: 0 | D22: 0 | E22: 0
B23: Total pasivos | C23: =C20+C21+C22 -> 980 | D23: =D20+D21+D22 -> 1060 | E23: =E20+E21+E22 -> 1430
B25: PATRIMONIO
B26: Patrimonio | C26: 6190 | D26: 6140 | E26: 5500
B27: Total pasivo y patrimonio | C27: =C23+C26 -> 7170 | D27: =D23+D26 -> 7200 | E27: =E23+E26 -> 6930
B29: Chequeo: Total activos - (Total pasivos + Patrimonio) | C29: =C14-C27 -> 0 | D29: =D14-D27 -> 0 | E29: =E14-E27 -> 0
B30: Estado del cuadre contable | C30: =IF(ABS(C29)<0.01,"Cuadrado","REVISAR DESCUADRE") -> Cuadrado | D30: =IF(ABS(D29)<0.01,"Cuadrado","REVISAR DESCUADRE") -> Cuadrado | E30: =IF(ABS(E29)<0.01,"Cuadrado","REVISAR DESCUADRE") -> Cuadrado
B32: Nota: si el chequeo no muestra 'Cuadrado', revise los inputs de activos, pasivos y patrimonio. Datos históricos de IHP tomados del caso de estudio 2023-2025; sustituya por los valores de la empresa real evaluada.

Sheet Flujo_3Años
B2: Flujo de Efectivo (método simplificado) — IHP
B3: Cifras en USD miles. Celdas azules = inputs editables; celdas verdes traen datos de otras hojas.
B5: Concepto (USD miles) | C5: 2023 | D5: 2024 | E5: 2025
B6: Saldo 2022 (referencia, no forma parte de 2023-2025): CxC neta / Inventarios / CxP | C6: CxC neta: | D6: Inventarios: | E6: CxP:
B7: Valores de referencia 2022 (USD miles) | C7: 3910 | D7: 1400 | E7: 480
B9: ACTIVIDADES OPERATIVAS
B10: Utilidad neta | C10: =ER_3Años!C17 -> 1325 | D10: =ER_3Años!D17 -> 1124 | E10: =ER_3Años!E17 -> 938
B11: Más: depreciación y amortización | C11: =-ER_3Años!C12 -> 60 | D11: =-ER_3Años!D12 -> 55 | E11: =-ER_3Años!E12 -> 50
B12: Menos: cambio en cuentas por cobrar (aumento resta) | C12: =-(BG_3Años!C8-C7) -> 70 | D12: =-(BG_3Años!D8-BG_3Años!C8) -> 90 | E12: =-(BG_3Años!E8-BG_3Años!D8) -> 150
B13: Menos: cambio en inventarios (aumento resta) | C13: =-(BG_3Años!C9-D7) -> -100 | D13: =-(BG_3Años!D9-BG_3Años!C9) -> -100 | E13: =-(BG_3Años!E9-BG_3Años!D9) -> -50
B14: Más: cambio en cuentas por pagar (aumento suma) | C14: =(BG_3Años!C17-E7) -> 20 | D14: =(BG_3Años!D17-BG_3Años!C17) -> 0 | E14: =(BG_3Años!E17-BG_3Años!D17) -> -20
B15: Otros cambios en capital de trabajo y partidas de conciliación (fórmula de cierre) | C15: =(BG_3Años!C7-900)-C10-C11-C12-C13-C14-C21-C26 -> 80 | D15: =(BG_3Años!D7-BG_3Años!C7)-D10-D11-D12-D13-D14-D21-D26 -> 155 | E15: =(BG_3Años!E7-BG_3Años!D7)-E10-E11-E12-E13-E14-E21-E26 -> 430
B16: Flujo neto de actividades operativas | C16: =SUM(C10:C15) -> 1455 | D16: =SUM(D10:D15) -> 1324 | E16: =SUM(E10:E15) -> 1498
B18: ACTIVIDADES DE INVERSIÓN
B19: Capex de mantenimiento | C19: -100 | D19: -100 | E19: -80
B20: Capex de expansión (proyecto Beauty Cream) | C20: 0 | D20: 0 | E20: 0
B21: Flujo neto de actividades de inversión | C21: =SUM(C19:C20) -> -100 | D21: =SUM(D19:D20) -> -100 | E21: =SUM(E19:E20) -> -80
B23: ACTIVIDADES DE FINANCIAMIENTO
B24: Deuda nueva / (amortización) | C24: 0 | D24: 0 | E24: 0
B25: Dividendos y retiros a accionistas | C25: -1145 | D25: -1174 | E25: -1578
B26: Flujo neto de actividades de financiamiento | C26: =SUM(C24:C25) -> -1145 | D26: =SUM(D24:D25) -> -1174 | E26: =SUM(E24:E25) -> -1578
B28: Variación neta de caja | C28: =C16+C21+C26 -> 210 | D28: =D16+D21+D26 -> 50 | E28: =E16+E21+E26 -> -160
B29: Caja inicial | C29: 900 | D29: =BG_3Años!C7 -> 1110 | E29: =BG_3Años!D7 -> 1160
B30: Caja final (debe coincidir con BG_3Años) | C30: =C29+C28 -> 1110 | D30: =D29+D28 -> 1160 | E30: =E29+E28 -> 1000
B31: Chequeo vs. Balance General (diferencia) | C31: =C30-BG_3Años!C7 -> 0 | D31: =D30-BG_3Años!D7 -> 0 | E31: =E30-BG_3Años!E7 -> 0
B33: Nota: el flujo de caja usa el método simplificado (utilidad neta + partidas no monetarias +/- cambios en capital de trabajo). Los cambios en CxC, inventarios y CxP se calculan por diferencia entre balances consecutivos (BG_3Años); para 2023 se usa el saldo de cierre de 2022 (fila de referencia) como año previo, dado que no hay balance 2022 completo en esta plantilla. La fila 'Otros cambios en capital de trabajo y partidas de conciliación' es una fórmula de cierre que garantiza que la caja final calculada coincida exactamente con la caja reportada en BG_3Años; en el caso IHP recoge efectos no explícitos en el balance resumido (p. ej. movimientos brutos de cartera y provisión). Si sustituye los datos por otra empresa con estados financieros completos, esta fila debería tender a cero.

Sheet Crédito_DSCR
B2: Estructura de Crédito y Cobertura de Servicio de Deuda (DSCR) — IHP
B3: Cifras en USD miles salvo tasa y plazo. Celdas azules = inputs editables; negro = fórmulas; verde = vínculos entre hojas.
B5: Términos del crédito propuesto
B6: Monto del crédito (USD miles) | C6: 3000
B7: Tasa de interés anual | C7: 0.12
B8: Plazo total (años) | C8: 6
B9: Año de desembolso | C9: 2026
B10: Años de gracia de capital | C10: 1
B11: Amortización anual de capital 2027-2031 (USD miles) | C11: 600
B13: Servicio de deuda y DSCR proyectado (2026-2031)
B14: Concepto (USD miles, salvo DSCR en veces) | C14: 2026 | D14: 2027 | E14: 2028 | F14: 2029 | G14: 2030 | H14: 2031
B15: Saldo de deuda al inicio del año | C15: =C6 -> 3000 | D15: =C17 -> 3000 | E15: =D17 -> 2400 | F15: =E17 -> 1800 | G15: =F17 -> 1200 | H15: =G17 -> 600
B16: Amortización de capital | C16: 0 | D16: =MIN(C11,D15) -> 600 | E16: =MIN(C11,E15) -> 600 | F16: =MIN(C11,F15) -> 600 | G16: =MIN(C11,G15) -> 600 | H16: =MIN(C11,H15) -> 600
B17: Saldo de deuda al cierre del año | C17: =C15-C16 -> 3000 | D17: =D15-D16 -> 2400 | E17: =E15-E16 -> 1800 | F17: =F15-F16 -> 1200 | G17: =G15-G16 -> 600 | H17: =H15-H16 -> 0
B18: Intereses (sobre saldo promedio) | C18: =AVERAGE(C15,C17)*C7 -> 360 | D18: =AVERAGE(D15,D17)*C7 -> 324 | E18: =AVERAGE(E15,E17)*C7 -> 252 | F18: =AVERAGE(F15,F17)*C7 -> 180 | G18: =AVERAGE(G15,G17)*C7 -> 108 | H18: =AVERAGE(H15,H17)*C7 -> 36
B19: Servicio total de deuda (interés + amortización) | C19: =C18+C16 -> 360 | D19: =D18+D16 -> 924 | E19: =E18+E16 -> 852 | F19: =F18+F16 -> 780 | G19: =G18+G16 -> 708 | H19: =H18+H16 -> 636
B20: EBITDA / flujo de caja disponible para servicio de deuda | C20: 822 | D20: 950 | E20: 1120 | F20: 1308 | G20: 1494 | H20: 1494
B21: DSCR (flujo disponible / servicio de deuda) | C21: =IF(C19=0,"",C20/C19) -> 2.2833333 | D21: =IF(D19=0,"",D20/D19) -> 1.0281385 | E21: =IF(E19=0,"",E20/E19) -> 1.314554 | F21: =IF(F19=0,"",F20/F19) -> 1.6769231 | G21: =IF(G19=0,"",G20/G19) -> 2.1101695 | H21: =IF(H19=0,"",H20/H19) -> 2.3490566
B23: Resumen de cobertura
B24: DSCR mínimo del período 2026-2031 | C24: =MIN(C21:H21) -> 1.0281385
B25: Semáforo del DSCR mínimo | C25: =IF(C24>=1.25,"Verde: aceptable",IF(C24>=1.1,"Amarillo: alerta","Rojo: revisión")) -> Rojo: revisión
B26: DSCR meta (línea de referencia) | C26: 1.25
B28: Serie auxiliar: DSCR meta (para gráfico)
B33: Serie auxiliar: DSCR meta (para gráfico) | C33: =$C$26 -> 1.25 | D33: =$C$26 -> 1.25 | E33: =$C$26 -> 1.25 | F33: =$C$26 -> 1.25 | G33: =$C$26 -> 1.25 | H33: =$C$26 -> 1.25

Sheet Indicadores
B2: Indicadores Financieros — IHP
B3: Cifras en USD miles salvo ratios. Fórmulas vinculadas a ER_3Años, BG_3Años y Flujo_3Años. Semáforo: verde=aceptable, amarillo=alerta, rojo=revisión.
B5: Indicador | C5: 2023 | D5: 2024 | E5: 2025 | G5: Fórmula | H5: Umbral (verde / amarillo / rojo) | I5: Estado 2025
B6: LIQUIDEZ Y CAPITAL DE TRABAJO
B7: Razón corriente (veces) | C7: =BG_3Años!C11/BG_3Años!C20 -> 6.8469388 | D7: =BG_3Años!D11/BG_3Años!D20 -> 6.3773585 | E7: =BG_3Años!E11/BG_3Años!E20 -> 4.5454545 | G7: Activo corriente / Pasivo corriente | H7: Verde ≥1.50x; Amarillo 1.00-1.49x; Rojo <1.00x | I7: =IF(E7>=1.5,"Verde: aceptable",IF(AND(E7>=1,E7<1.5),"Amarillo: alerta","Rojo: revisión")) -> Verde: aceptable
B8: Prueba ácida (veces) | C8: =(BG_3Años!C7+BG_3Años!C8)/BG_3Años!C20 -> 5.0510204 | D8: =(BG_3Años!D7+BG_3Años!D8)/BG_3Años!D20 -> 4.6320755 | E8: =(BG_3Años!E7+BG_3Años!E8)/BG_3Años!E20 -> 3.2167832 | G8: (Caja + CxC neta) / Pasivo corriente | H8: Verde ≥1.00x; Amarillo 0.75-0.99x; Rojo <0.75x | I8: =IF(E8>=1,"Verde: aceptable",IF(AND(E8>=0.75,E8<1),"Amarillo: alerta","Rojo: revisión")) -> Verde: aceptable
B9: Capital de trabajo / Activos totales | C9: =(BG_3Años!C11-BG_3Años!C20)/BG_3Años!C14 -> 0.79916318 | D9: =(BG_3Años!D11-BG_3Años!D20)/BG_3Años!D14 -> 0.79166667 | E9: =(BG_3Años!E11-BG_3Años!E20)/BG_3Años!E14 -> 0.73160173 | G9: (Activo corriente - Pasivo corriente) / Activos totales | H9: Verde ≥20%; Amarillo 5%-19.9%; Rojo <5% | I9: =IF(E9>=0.2,"Verde: aceptable",IF(AND(E9>=0.05,E9<0.2),"Amarillo: alerta","Rojo: revisión")) -> Verde: aceptable
B10: ENDEUDAMIENTO
B11: Deuda total / Patrimonio (veces) | C11: =BG_3Años!C23/BG_3Años!C26 -> 0.15831987 | D11: =BG_3Años!D23/BG_3Años!D26 -> 0.17263844 | E11: =BG_3Años!E23/BG_3Años!E26 -> 0.26 | G11: Total pasivos / Patrimonio | H11: Verde ≤1.50x; Amarillo >1.50x-2.50x; Rojo >2.50x | I11: =IF(E11<=1.5,"Verde: aceptable",IF(AND(E11>1.5,E11<=2.5),"Amarillo: alerta","Rojo: revisión")) -> Verde: aceptable
B12: Pasivo total / Activo total | C12: =BG_3Años!C23/BG_3Años!C14 -> 0.13668061 | D12: =BG_3Años!D23/BG_3Años!D14 -> 0.14722222 | E12: =BG_3Años!E23/BG_3Años!E14 -> 0.20634921 | G12: Total pasivos / Total activos | H12: Verde ≤60%; Amarillo >60%-75%; Rojo >75% | I12: =IF(E12<=0.6,"Verde: aceptable",IF(AND(E12>0.6,E12<=0.75),"Amarillo: alerta","Rojo: revisión")) -> Verde: aceptable
B13: Deuda financiera neta / EBITDA (veces) | C13: =IF(ER_3Años!C19<=0,"N/A (EBITDA<=0)",((BG_3Años!C18+BG_3Años!C21)-BG_3Años!C7)/ER_3Años!C19) -> -0.53365385 | D13: =IF(ER_3Años!D19<=0,"N/A (EBITDA<=0)",((BG_3Años!D18+BG_3Años!D21)-BG_3Años!D7)/ER_3Años!D19) -> -0.65685164 | E13: =IF(ER_3Años!E19<=0,"N/A (EBITDA<=0)",((BG_3Años!E18+BG_3Años!E21)-BG_3Años!E7)/ER_3Años!E19) -> -0.67430883 | G13: (Deuda financiera CP+LP - Caja) / EBITDA | H13: Verde ≤3.0x; Amarillo >3.0x-4.0x; Rojo >4.0x o EBITDA≤0 | I13: =IF(ISTEXT(E13),"Rojo: revisión",IF(E13<=3,"Verde: aceptable",IF(E13<=4,"Amarillo: alerta","Rojo: revisión"))) -> Verde: aceptable
B14: RENTABILIDAD
B15: Margen bruto | C15: =ER_3Años!C8/ER_3Años!C6 -> 0.32 | D15: =ER_3Años!D8/ER_3Años!D6 -> 0.31 | E15: =ER_3Años!E8/ER_3Años!E6 -> 0.295 | G15: Utilidad bruta / Ventas | H15: Verde ≥25%; Amarillo 15%-24.9%; Rojo <15% | I15: =IF(E15>=0.25,"Verde: aceptable",IF(AND(E15>=0.15,E15<0.25),"Amarillo: alerta","Rojo: revisión")) -> Verde: aceptable
B16: Margen EBIT | C16: =ER_3Años!C13/ER_3Años!C6 -> 0.1530303 | D16: =ER_3Años!D13/ER_3Años!D6 -> 0.13579365 | E16: =ER_3Años!E13/ER_3Años!E6 -> 0.11941667 | G16: EBIT / Ventas | H16: Verde ≥10%; Amarillo 5%-9.9%; Rojo <5% | I16: =IF(E16>=0.1,"Verde: aceptable",IF(AND(E16>=0.05,E16<0.1),"Amarillo: alerta","Rojo: revisión")) -> Verde: aceptable
B17: Margen neto | C17: =ER_3Años!C17/ER_3Años!C6 -> 0.10037879 | D17: =ER_3Años!D17/ER_3Años!D6 -> 0.089206349 | E17: =ER_3Años!E17/ER_3Años!E6 -> 0.078166667 | G17: Utilidad neta / Ventas | H17: Verde ≥5%; Amarillo 1%-4.9%; Rojo <1% | I17: =IF(E17>=0.05,"Verde: aceptable",IF(AND(E17>=0.01,E17<0.05),"Amarillo: alerta","Rojo: revisión")) -> Verde: aceptable
B18: ROA (retorno sobre activos) | C18: =ER_3Años!C17/BG_3Años!C14 -> 0.18479777 | D18: =ER_3Años!D17/BG_3Años!D14 -> 0.15611111 | E18: =ER_3Años!E17/BG_3Años!E14 -> 0.13535354 | G18: Utilidad neta / Activos totales | H18: Verde ≥5%; Amarillo 1%-4.9%; Rojo <1% | I18: =IF(E18>=0.05,"Verde: aceptable",IF(AND(E18>=0.01,E18<0.05),"Amarillo: alerta","Rojo: revisión")) -> Verde: aceptable
B19: ROE (retorno sobre patrimonio) | C19: =ER_3Años!C17/BG_3Años!C26 -> 0.21405493 | D19: =ER_3Años!D17/BG_3Años!D26 -> 0.18306189 | E19: =ER_3Años!E17/BG_3Años!E26 -> 0.17054545 | G19: Utilidad neta / Patrimonio | H19: Verde ≥10%; Amarillo 3%-9.9%; Rojo <3% | I19: =IF(E19>=0.1,"Verde: aceptable",IF(AND(E19>=0.03,E19<0.1),"Amarillo: alerta","Rojo: revisión")) -> Verde: aceptable
B20: Rotación de activos (veces) | C20: =ER_3Años!C6/BG_3Años!C14 -> 1.8410042 | D20: =ER_3Años!D6/BG_3Años!D14 -> 1.75 | E20: =ER_3Años!E6/BG_3Años!E14 -> 1.7316017 | G20: Ventas / Activos totales | H20: Verde ≥1.0x; Amarillo 0.6x-0.99x; Rojo <0.6x | I20: =IF(E20>=1,"Verde: aceptable",IF(AND(E20>=0.6,E20<1),"Amarillo: alerta","Rojo: revisión")) -> Verde: aceptable
B21: CICLO DE CONVERSIÓN DE EFECTIVO
B22: Rotación de inventarios (veces) | C22: =-ER_3Años!C7/(BG_3Años!C9) -> 5.984 | D22: =-ER_3Años!D7/(AVERAGE(BG_3Años!D9,BG_3Años!C9)) -> 5.6090323 | E22: =-ER_3Años!E7/(AVERAGE(BG_3Años!E9,BG_3Años!D9)) -> 5.2061538 | G22: COGS / Inventario promedio | H22: Referencial (ver Días de inventario)
B23: Días de inventario (DIO) | C23: =365/C22 -> 60.995989 | D23: =365/D22 -> 65.073614 | E23: =365/E22 -> 70.109338 | G23: 365 / Rotación de inventarios | H23: Verde ≤90 días; Amarillo 91-120; Rojo >120 | I23: =IF(E23<=90,"Verde: aceptable",IF(AND(E23>90,E23<=120),"Amarillo: alerta","Rojo: revisión")) -> Verde: aceptable
B24: Rotación de cuentas por cobrar (veces) | C24: =ER_3Años!C6/(BG_3Años!C8) -> 3.4375 | D24: =ER_3Años!D6/(AVERAGE(BG_3Años!D8,BG_3Años!C8)) -> 3.3201581 | E24: =ER_3Años!E6/(AVERAGE(BG_3Años!E8,BG_3Años!D8)) -> 3.2653061 | G24: Ventas / CxC promedio | H24: Referencial (ver DSO)
B25: DSO (días de venta pendientes de cobro) | C25: =365/C24 -> 106.18182 | D25: =365/D24 -> 109.93452 | E25: =365/E24 -> 111.78125 | G25: 365 / Rotación de CxC | H25: Verde ≤60 días; Amarillo 61-90; Rojo >90 | I25: =IF(E25<=60,"Verde: aceptable",IF(AND(E25>60,E25<=90),"Amarillo: alerta","Rojo: revisión")) -> Rojo: revisión
B26: Rotación de cuentas por pagar (veces) | C26: =-ER_3Años!C7/(BG_3Años!C17) -> 17.952 | D26: =-ER_3Años!D7/(AVERAGE(BG_3Años!D17,BG_3Años!C17)) -> 17.388 | E26: =-ER_3Años!E7/(AVERAGE(BG_3Años!E17,BG_3Años!D17)) -> 17.265306 | G26: COGS / CxP promedio | H26: Referencial (ver DPO)
B27: DPO (días de pago a proveedores) | C27: =365/C26 -> 20.331996 | D27: =365/D26 -> 20.991488 | E27: =365/E26 -> 21.140662 | G27: 365 / Rotación de CxP | H27: Verde 30-90 días; Amarillo 15-29 o 91-120; Rojo <15 o >120 | I27: =IF(AND(E27>=30,E27<=90),"Verde: aceptable",IF(OR(AND(E27>=15,E27<30),AND(E27>90,E27<=120)),"Amarillo: alerta","Rojo: revisión")) -> Amarillo: alerta
B28: Ciclo de conversión de efectivo (días) | C28: =C25+C23-C27 -> 146.84581 | D28: =D25+D23-D27 -> 154.01665 | E28: =E25+E23-E27 -> 160.74993 | G28: DSO + Días inventario - DPO | H28: Verde ≤90 días; Amarillo 91-120; Rojo >120 | I28: =IF(E28<=90,"Verde: aceptable",IF(AND(E28>90,E28<=120),"Amarillo: alerta","Rojo: revisión")) -> Rojo: revisión
B29: ANÁLISIS DUPONT
B30: Multiplicador de patrimonio (veces) | C30: =BG_3Años!C14/BG_3Años!C26 -> 1.1583199 | D30: =BG_3Años!D14/BG_3Años!D26 -> 1.1726384 | E30: =BG_3Años!E14/BG_3Años!E26 -> 1.26 | G30: Activos totales / Patrimonio | H30: Referencial
B31: Índice DuPont (ROE) = margen neto x rotación de activos x multiplicador | C31: =C17*C20*C30 -> 0.21405493 | D31: =D17*D20*D30 -> 0.18306189 | E31: =E17*E20*E30 -> 0.17054545 | G31: Margen neto x Rotación de activos x Multiplicador de patrimonio | H31: Debe igualar al ROE calculado directamente
B33: Metodología de promedios: los indicadores de rotación e inventario/CxC/CxP usan el promedio entre el saldo del año y el del año anterior (inventario, cartera y cuentas por pagar promedio). Para 2023, al no existir un balance 2022 completo en esta plantilla, se utiliza el saldo de cierre de 2023 como alternativa documentada (en vez de un promedio). Sustituya esta alternativa por el promedio real si dispone del balance del año anterior. El índice DuPont (margen neto x rotación de activos x multiplicador de patrimonio) debe coincidir con el ROE calculado directamente arriba; ambos se muestran para fines de verificación cruzada.

Sheet Altman_Z
B2: Modelo Altman Z-Score — IHP
B3: Z = 1.2·X1 + 1.4·X2 + 3.3·X3 + 0.6·X4 + 1.0·X5. Cifras en USD miles salvo ratios. Empresa privada: X4 usa aproximación (ver nota).
B5: Concepto | C5: 2023 | D5: 2024 | E5: 2025
B6: Inputs específicos del modelo (empresa privada)
B7: Valor estimado del patrimonio (aprox. mercado) | C7: =BG_3Años!C26 -> 6190 | D7: =BG_3Años!D26 -> 6140 | E7: =BG_3Años!E26 -> 5500
B8: Utilidades retenidas estimadas | C8: =C7-2000 -> 4190 | D8: =D7-2000 -> 4140 | E8: =E7-2000 -> 3500
B10: Variables tomadas de otras hojas
B11: Activos corrientes | C11: =BG_3Años!C11 -> 6710 | D11: =BG_3Años!D11 -> 6760 | E11: =BG_3Años!E11 -> 6500
B12: Pasivos corrientes | C12: =BG_3Años!C20 -> 980 | D12: =BG_3Años!D20 -> 1060 | E12: =BG_3Años!E20 -> 1430
B13: Capital de trabajo | C13: =C11-C12 -> 5730 | D13: =D11-D12 -> 5700 | E13: =E11-E12 -> 5070
B14: Activos totales | C14: =BG_3Años!C14 -> 7170 | D14: =BG_3Años!D14 -> 7200 | E14: =BG_3Años!E14 -> 6930
B15: EBIT | C15: =ER_3Años!C13 -> 2020 | D15: =ER_3Años!D13 -> 1711 | E15: =ER_3Años!E13 -> 1433
B16: Ventas | C16: =ER_3Años!C6 -> 13200 | D16: =ER_3Años!D6 -> 12600 | E16: =ER_3Años!E6 -> 12000
B17: Deuda total (total pasivos) | C17: =BG_3Años!C23 -> 980 | D17: =BG_3Años!D23 -> 1060 | E17: =BG_3Años!E23 -> 1430
B19: Componentes del Z-Score
B20: X1 = Capital de trabajo / Activos totales | C20: =C13/C14 -> 0.79916318 | D20: =D13/D14 -> 0.79166667 | E20: =E13/E14 -> 0.73160173
B21: X2 = Utilidades retenidas / Activos totales | C21: =C8/C14 -> 0.58437936 | D21: =D8/D14 -> 0.575 | E21: =E8/E14 -> 0.50505051
B22: X3 = EBIT / Activos totales | C22: =C15/C14 -> 0.28172943 | D22: =D15/D14 -> 0.23763889 | E22: =E15/E14 -> 0.20678211
B23: X4 = Valor de mercado del patrimonio / Deuda total | C23: =C7/C17 -> 6.3163265 | D23: =D7/D17 -> 5.7924528 | E23: =E7/E17 -> 3.8461538
B24: X5 = Ventas / Activos totales | C24: =C16/C14 -> 1.8410042 | D24: =D16/D14 -> 1.75 | E24: =E16/E14 -> 1.7316017
B26: Z-Score | C26: =1.2*C20+1.4*C21+3.3*C22+0.6*C23+1*C24 -> 8.3376341 | D26: =1.2*D20+1.4*D21+3.3*D22+0.6*D23+1*D24 -> 7.76468 | E26: =1.2*E20+1.4*E21+3.3*E22+0.6*E23+1*E24 -> 6.3066678
B27: Clasificación | C27: =IF(C26>2.99,"Zona segura",IF(C26>=1.81,"Zona gris","Zona de angustia")) -> Zona segura | D27: =IF(D26>2.99,"Zona segura",IF(D26>=1.81,"Zona gris","Zona de angustia")) -> Zona segura | E27: =IF(E26>2.99,"Zona segura",IF(E26>=1.81,"Zona gris","Zona de angustia")) -> Zona segura
B29: Nota metodológica: IHP es una empresa privada sin cotización bursátil. X4 (valor de mercado del patrimonio/deuda total) usa una aproximación: el patrimonio contable como proxy conservador del valor de mercado del patrimonio, y el total de pasivos como deuda total. El valor estimado del patrimonio y las utilidades retenidas son inputs editables (celdas azules); en el caso IHP se precargan a partir del patrimonio contable de BG_3Años y de un capital social y reservas no distribuibles estimado en USD 2.000 miles (constante), consistente con el caso de estudio. Ajuste estos supuestos si dispone de una valoración independiente o de datos societarios reales. Clasificación: zona segura Z>2.99; zona gris 1.81≤Z≤2.99; zona de angustia Z<1.81. El resultado es una señal complementaria de solvencia patrimonial y no sustituye el análisis de flujo de caja, cartera, garantías ni riesgos cualitativos.
B35: Series auxiliares para gráfico (líneas de corte)
B36: Corte zona segura (2.99) | C36: 2.99 | D36: 2.99 | E36: 2.99
B37: Corte zona gris (1.81) | C37: 1.81 | D37: 1.81 | E37: 1.81
B63: Ubicación del año más reciente (2025) en la escala Altman Z-Score
B64: Z-Score 2025 (resultado destacado) | C64: =E26 -> 6.3066678
B65: Zona (fórmula automática) | C65: =E27 -> Zona segura
B67: Segmento de escala | C67: Ancho
B68: Zona de angustia (<1.81) | C68: 1.81
B69: Zona gris (1.81-2.99) | C69: 1.18
B70: Zona segura (>2.99, tramo mostrado) | C70: 2
B72: Escala visual: zonas de clasificación Altman Z-Score (2025)
B73: La escala siguiente distingue las tres zonas por color y ubica automáticamente el Z-Score de 2025 (columna E) mediante fórmulas.
B75: Parámetros de la escala (fórmulas)
B76: Corte zona de angustia / gris (1.81) | C76: =C37 -> 1.81
B77: Corte zona gris / segura (2.99) | C77: =C36 -> 2.99
B78: Máximo mostrado en la escala | C78: =MAX(C36+2, E26+1) -> 7.3066678
B79: Z-Score 2025 (posición a ubicar) | C79: =E26 -> 6.3066678
...

Sheet Matriz_Decisión
B2: Matriz de Decisión Crediticia — Rúbrica de Evaluación
B3: Pesos y criterios según la rúbrica del caso. Nivel de desempeño 1-4 (lista desplegable). Puntos = Peso x Nivel / 4.
B5: Criterio | C5: Peso | D5: Nivel (1-4) | E5: Cálculo | F5: Puntos | G5: Observaciones del analista (editable) | H5: Nota rápida de nivel
B6: Comprensión del negocio y riesgos sectoriales | C6: 10 | D6: 3 | E6: =C6*D6/4 -> 7.5 | F6: =C6*D6/4 -> 7.5 | H6: =CHOOSE(D6,"1: Insuficiente","2: En desarrollo","3: Competente","4: Sobresaliente") -> 3: Competente
B7: Análisis de desempeño histórico | C7: 12 | D7: 3 | E7: =C7*D7/4 -> 9 | F7: =C7*D7/4 -> 9 | H7: =CHOOSE(D7,"1: Insuficiente","2: En desarrollo","3: Competente","4: Sobresaliente") -> 3: Competente
B8: Liquidez, cartera y capital de trabajo | C8: 15 | D8: 3 | E8: =C8*D8/4 -> 11.25 | F8: =C8*D8/4 -> 11.25 | H8: =CHOOSE(D8,"1: Insuficiente","2: En desarrollo","3: Competente","4: Sobresaliente") -> 3: Competente
B9: Capacidad de pago y flujo de caja | C9: 15 | D9: 3 | E9: =C9*D9/4 -> 11.25 | F9: =C9*D9/4 -> 11.25 | H9: =CHOOSE(D9,"1: Insuficiente","2: En desarrollo","3: Competente","4: Sobresaliente") -> 3: Competente
B10: Evaluación del proyecto Beauty Cream | C10: 10 | D10: 3 | E10: =C10*D10/4 -> 7.5 | F10: =C10*D10/4 -> 7.5 | H10: =CHOOSE(D10,"1: Insuficiente","2: En desarrollo","3: Competente","4: Sobresaliente") -> 3: Competente
B11: Riesgos, estrés y clasificación crediticia | C11: 10 | D11: 3 | E11: =C11*D11/4 -> 7.5 | F11: =C11*D11/4 -> 7.5 | H11: =CHOOSE(D11,"1: Insuficiente","2: En desarrollo","3: Competente","4: Sobresaliente") -> 3: Competente
B12: Garantías, condiciones y covenants | C12: 13 | D12: 3 | E12: =C12*D12/4 -> 9.75 | F12: =C12*D12/4 -> 9.75 | H12: =CHOOSE(D12,"1: Insuficiente","2: En desarrollo","3: Competente","4: Sobresaliente") -> 3: Competente
B13: Incumplimiento y recuperación | C13: 5 | D13: 3 | E13: =C13*D13/4 -> 3.75 | F13: =C13*D13/4 -> 3.75 | H13: =CHOOSE(D13,"1: Insuficiente","2: En desarrollo","3: Competente","4: Sobresaliente") -> 3: Competente
B14: Decisión de crédito y estructura propuesta | C14: 7 | D14: 3 | E14: =C14*D14/4 -> 5.25 | F14: =C14*D14/4 -> 5.25 | H14: =CHOOSE(D14,"1: Insuficiente","2: En desarrollo","3: Competente","4: Sobresaliente") -> 3: Competente
B15: Comunicación, evidencia y defensa | C15: 3 | D15: 3 | E15: =C15*D15/4 -> 2.25 | F15: =C15*D15/4 -> 2.25 | H15: =CHOOSE(D15,"1: Insuficiente","2: En desarrollo","3: Competente","4: Sobresaliente") -> 3: Competente
B16: TOTAL | C16: =SUM(C6:C15) -> 100 | F16: =SUM(F6:F15) -> 75
B18: Calificación final y banda de desempeño
B19: Puntuación total / 100 | C19: =F16 -> 75
B20: Banda de desempeño | C20: =IF(C19>=90,"Sobresaliente",IF(C19>=80,"Muy competente",IF(C19>=70,"Competente",IF(C19>=60,"En desarrollo","Insuficiente")))) -> Competente
B22: Referencia de bandas: 90-100 Sobresaliente; 80-89 Muy competente; 70-79 Competente; 60-69 En desarrollo; <60 Insuficiente
B24: Decisión crediticia sugerida
B25: Decisión (editable por el analista) | C25: Aprobar condicionado
B27: Interpretación automática
B28: =IF(C19>=80,"Puntuación >= 80: hay calidad técnica alta en el análisis presentado, pero la decisión final depende de la capacidad de pago, las garantías y las políticas de la institución. No debe aprobarse automáticamente por el puntaje.",IF(C19>=60,"Puntuación entre 60 y 79: el análisis requiere mitigantes y correcciones antes de sustentar una aprobación; revise en particular capacidad de pago, cartera y garantías.","Puntuación menor a 60: el análisis no sustenta una aprobación de crédito en su estado actual.")) -> Puntuación entre 60 y 79: el análisis requiere mitigantes y correcciones antes de sustentar una aprobación; revise en particular capacidad de pago, cartera y garantías.
B33: Tabla de referencia: descriptores generales de la rúbrica (niveles 4, 3, 2, 1)
B34: Criterio | C34: Nivel 4: Sobresaliente | D34: Nivel 3: Competente | E34: Nivel 2: En desarrollo | F34: Nivel 1: Insuficiente
B35: Comprensión del negocio y riesgos sectoriales | C35: Relaciona modelo de negocio, segmentos C-D-E, competencia, dependencia de importaciones, cobertura geográfica, riesgo laboral y Beauty Cream con la decisión crediticia | D35: Identifica la mayoría de los riesgos de negocio y explica su efecto general | E35: Menciona riesgos sin priorizarlos o sin vincularlos con capacidad de pago | F35: Describe la empresa de forma superficial o ignora riesgos sectoriales relevantes
B36: Análisis de desempeño histórico | C36: Analiza tendencia 2021-2025 de ventas, márgenes, EBIT, utilidad neta, gastos, provisiones y distribuciones; explica causas y efectos en el riesgo | D36: Calcula e interpreta la mayoría de las tendencias principales | E36: Presenta algunas cifras, pero con análisis limitado o errores menores | F36: Se limita a copiar cifras o llega a conclusiones no sustentadas
B37: Liquidez, cartera y capital de trabajo | C37: Diferencia liquidez contable de liquidez realizable; analiza razón corriente, DSO, inventarios, días de pago, ciclo de caja y cartera vencida; ajusta cartera por recuperabilidad | D37: Identifica el deterioro del ciclo de caja y la concentración de cartera, con ajustes razonables | E37: Reconoce que la cartera es riesgosa, pero no cuantifica su efecto en caja o liquidez | F37: Considera la razón corriente como evidencia suficiente de solvencia o ignora cartera vencida
B38: Capacidad de pago y flujo de caja | C38: Reconstruye flujo disponible, DSCR, servicio de deuda y necesidades de capital de trabajo; incorpora impuestos, mantenimiento, intereses y sensibilidades | D38: Calcula o interpreta correctamente DSCR y flujo de caja, aunque con menor profundidad en supuestos | E38: Usa utilidad neta como indicador principal sin convertirla adecuadamente en caja | F38: No analiza flujo de caja ni cobertura de deuda
B39: Evaluación del proyecto Beauty Cream | C39: Separa operación tradicional y nueva línea; analiza ingresos, márgenes, costos de lanzamiento, permisos, competencia, cronograma y riesgo de ejecución | D39: Evalúa razonablemente las premisas comerciales y financieras del proyecto | E39: Acepta o rechaza proyecciones sin contrastar supuestos relevantes | F39: Ignora que una parte importante del crecimiento depende de Beauty Cream
B40: Riesgos, estrés y clasificación crediticia | C40: Prioriza riesgos de negocio, contraparte, mercado, operación, laboral, legal y ejecución; cuantifica o explica el escenario de estrés y sus consecuencias sobre DSCR y liquidez | D40: Identifica riesgos principales y propone una prueba de estrés razonable | E40: Enumera riesgos sin priorización, métricas o consecuencias claras | F40: Omite riesgos críticos o sostiene que la garantía elimina el riesgo
B41: Garantías, condiciones y covenants | C41: Diseña garantías diversificadas y verificables; distingue valor contable y de realización; propone condiciones precedentes, aporte propio, covenants, cuenta controlada, seguros y monitoreo | D41: Propone un paquete de garantías y covenants pertinente, aunque con menor detalle de perfeccionamiento | E41: Sugiere garantías genéricas sin considerar registro, valor de liquidación o calidad de activos | F41: Confía exclusivamente en activos depreciados o no plantea controles de riesgo
B42: Incumplimiento y recuperación | C42: Distingue alerta temprana, cura, vencimiento anticipado, cobranza, preservación de evidencia y ejecución de garantías; adapta el proceso al tipo de garantía | D42: Propone un procedimiento lógico de actuación ante incumplimiento | E42: Menciona acciones de cobro sin secuencia o sin diferenciar garantías | F42: No considera recuperación, cumplimiento ni ejecución
B43: Decisión de crédito y estructura propuesta | C43: Emite una decisión inequívoca y justificada; define monto, plazo, gracia, amortización, desembolsos por hitos y condiciones de aprobación o rechazo | D43: Presenta decisión y estructura mayormente coherentes con el análisis | E43: La decisión es ambigua o no corresponde con los hallazgos | F43: La recomendación no tiene justificación ni estructura financiera
B44: Comunicación, evidencia y defensa | C44: Presenta informe claro, profesional, consistente, con cálculos verificables, supuestos explícitos y capacidad de responder objeciones del comité | D44: Presenta evidencia suficiente y comunica con claridad general | E44: El informe es desordenado, con supuestos implícitos o cálculos difíciles de verificar | F44: La presentación carece de evidencia, orden o coherencia

Sheet Guía_Rangos
B2: Guía de Rangos e Interpretación de Indicadores
B3: Umbrales orientativos para manufactura; ajustar por sector, moneda, estacionalidad y proyecto. Alineados con el formato condicional de 'Indicadores', 'Crédito_DSCR' y 'Altman_Z'.
B5: Aclaraciones generales
B6: Los umbrales de esta guía son orientativos para empresas manufactureras y pueden variar según moneda, sector, estacionalidad y naturaleza del proyecto financiado. En el caso de Industrias de Higiene Popular (IHP), la empresa depende de insumos importados pagados de contado y vende una parte relevante a crédito con cobranza lenta; por ello, el DSO, el ciclo de conversión de efectivo y el DSCR son particularmente relevantes para la decisión de crédito y deben analizarse con mayor rigor que en un caso genérico.
B10: Indicador | C10: Fórmula / definición breve | D10: Verde: Aceptable | E10: Amarillo: Alerta | F10: Rojo: Revisión | G10: Observación
B11: Razón corriente | C11: Activo corriente / Pasivo corriente | D11: ≥1.50x | E11: 1.00x - 1.49x | F11: <1.00x | G11: Liquidez contable general
B12: Prueba ácida | C12: (Caja + CxC neta) / Pasivo corriente | D12: ≥1.00x | E12: 0.75x - 0.99x | F12: <0.75x | G12: Excluye inventarios
B13: Capital de trabajo / Activos | C13: (Activo corriente - Pasivo corriente) / Activos totales | D13: ≥20% | E13: 5% - 19.9% | F13: <5% | G13: Holgura de capital de trabajo
B14: Deuda total / Patrimonio | C14: Total pasivos / Patrimonio | D14: ≤1.50x | E14: >1.50x - 2.50x | F14: >2.50x | G14: Apalancamiento total
B15: Pasivo total / Activo total | C15: Total pasivos / Total activos | D15: ≤60% | E15: >60% - 75% | F15: >75% | G15: Proporción de activos financiada con deuda
B16: Deuda financiera neta / EBITDA | C16: (Deuda financiera - Caja) / EBITDA | D16: ≤3.0x | E16: >3.0x - 4.0x | F16: >4.0x o EBITDA≤0 | G16: Cobertura de apalancamiento financiero
B17: Margen bruto | C17: Utilidad bruta / Ventas | D17: ≥25% | E17: 15% - 24.9% | F17: <15% | G17: Rentabilidad antes de gastos operativos
B18: Margen EBIT | C18: EBIT / Ventas | D18: ≥10% | E18: 5% - 9.9% | F18: <5% | G18: Rentabilidad operativa
B19: Margen neto | C19: Utilidad neta / Ventas | D19: ≥5% | E19: 1% - 4.9% | F19: <1% | G19: Rentabilidad final
B20: ROA | C20: Utilidad neta / Activos totales | D20: ≥5% | E20: 1% - 4.9% | F20: <1% | G20: Eficiencia en el uso de activos
B21: ROE | C21: Utilidad neta / Patrimonio | D21: ≥10% | E21: 3% - 9.9% | F21: <3% | G21: Retorno para los accionistas
... B28: Altman Z-Score | C28: 1.2X1+1.4X2+3.3X3+0.6X4+1.0X5 | D28: >2.99 (zona segura) | E28: 1.81 - 2.99 (zona gris) | F28: <1.81 (zona de angustia) | G28: Ver hoja Altman_Z; aproximación para empresa no cotizada
